Exception in thread Thread-2:
Traceback (most recent call last):
  File "C:\Users\lpy\AppData\Local\Programs\Python\Python39\lib\threading.py", line 973, in _bootstrap_inner
    self.run()
  File "C:\Users\lpy\AppData\Local\Programs\Python\Python39\lib\threading.py", line 910, in run
    self._target(*self._args, **self._kwargs)
  File "C:\Users\lpy\Desktop\bilibili-api\general.py", line 618, in _
    cmd = download_1(i)
  File "C:\Users\lpy\Desktop\bilibili-api\general.py", line 604, in download_1
    P = download_video(bv, self.header, path=setting["path"])
  File "C:\Users\lpy\Desktop\bilibili-api\module\func.py", line 502, in download_video
    s.set.append({"bv": bv, "byheader": {"user-agent": headers["user-agent"], "cookie": headers["cookie"][1, 20]+"..."}, "path": path})
AttributeError: 'dict' object has no attribute 'append'
Exception in thread Thread-3:
Traceback (most recent call last):
  File "C:\Users\lpy\AppData\Local\Programs\Python\Python39\lib\threading.py", line 973, in _bootstrap_inner
    self.run()
  File "C:\Users\lpy\AppData\Local\Programs\Python\Python39\lib\threading.py", line 910, in run
    self._target(*self._args, **self._kwargs)
  File "C:\Users\lpy\Desktop\bilibili-api\general.py", line 618, in _
    cmd = download_1(i)
  File "C:\Users\lpy\Desktop\bilibili-api\general.py", line 604, in download_1
    P = download_video(bv, self.header, path=setting["path"])
  File "C:\Users\lpy\Desktop\bilibili-api\module\func.py", line 502, in download_video
    s.set.append({"bv": bv, "byheader": {"user-agent": headers["user-agent"], "cookie": headers["cookie"][1, 20]+"..."}, "path": path})
AttributeError: 'dict' object has no attribute 'append'
Exception in thread Thread-5:
Traceback (most recent call last):
  File "C:\Users\lpy\AppData\Local\Programs\Python\Python39\lib\threading.py", line 973, in _bootstrap_inner
    self.run()
  File "C:\Users\lpy\AppData\Local\Programs\Python\Python39\lib\threading.py", line 910, in run
    self._target(*self._args, **self._kwargs)
  File "C:\Users\lpy\Desktop\bilibili-api\general.py", line 618, in _
    cmd = download_1(i)
  File "C:\Users\lpy\Desktop\bilibili-api\general.py", line 604, in download_1
    P = download_video(bv, self.header, path=setting["path"])
  File "C:\Users\lpy\Desktop\bilibili-api\module\func.py", line 502, in download_video
    s.set.append({"bv": bv, "byheader": {"user-agent": headers["user-agent"], "cookie": headers["cookie"][1, 20]+"..."}, "path": path})
AttributeError: 'dict' object has no attribute 'append'
Exception in thread Thread-6:
Traceback (most recent call last):
  File "C:\Users\lpy\AppData\Local\Programs\Python\Python39\lib\threading.py", line 973, in _bootstrap_inner
    self.run()
  File "C:\Users\lpy\AppData\Local\Programs\Python\Python39\lib\threading.py", line 910, in run
    self._target(*self._args, **self._kwargs)
  File "C:\Users\lpy\Desktop\bilibili-api\general.py", line 618, in _
    cmd = download_1(i)
  File "C:\Users\lpy\Desktop\bilibili-api\general.py", line 604, in download_1
    P = download_video(bv, self.header, path=setting["path"])
  File "C:\Users\lpy\Desktop\bilibili-api\module\func.py", line 502, in download_video
    s.set.append({"bv": bv, "byheader": {"user-agent": headers["user-agent"], "cookie": headers["cookie"][1, 20]+"..."}, "path": path})
AttributeError: 'dict' object has no attribute 'append'
Exception in thread Thread-7:
Traceback (most recent call last):
  File "C:\Users\lpy\AppData\Local\Programs\Python\Python39\lib\threading.py", line 973, in _bootstrap_inner
    self.run()
  File "C:\Users\lpy\AppData\Local\Programs\Python\Python39\lib\threading.py", line 910, in run
    self._target(*self._args, **self._kwargs)
  File "C:\Users\lpy\Desktop\bilibili-api\general.py", line 618, in _
    cmd = download_1(i)
  File "C:\Users\lpy\Desktop\bilibili-api\general.py", line 604, in download_1
    P = download_video(bv, self.header, path=setting["path"])
  File "C:\Users\lpy\Desktop\bilibili-api\module\func.py", line 502, in download_video
    s.set.append({"bv": bv, "byheader": {"user-agent": headers["user-agent"], "cookie": headers["cookie"][1, 20]+"..."}, "path": path})
AttributeError: 'dict' object has no attribute 'append'
Exception in thread Thread-2:
Traceback (most recent call last):
  File "C:\Users\lpy\AppData\Local\Programs\Python\Python39\lib\threading.py", line 973, in _bootstrap_inner
    self.run()
  File "C:\Users\lpy\AppData\Local\Programs\Python\Python39\lib\threading.py", line 910, in run
    self._target(*self._args, **self._kwargs)
  File "C:\Users\lpy\Desktop\bilibili-api\general.py", line 618, in _
    cmd = download_1(i)
  File "C:\Users\lpy\Desktop\bilibili-api\general.py", line 604, in download_1
    P = download_video(bv, self.header, path=setting["path"])
  File "C:\Users\lpy\Desktop\bilibili-api\module\func.py", line 502, in download_video
    s.set.append({"bv": bv, "byheader": {"user-agent": headers["user-agent"], "cookie": headers["cookie"][1, 20]+"..."}, "path": path})
AttributeError: 'dict' object has no attribute 'append'
Exception in thread Thread-3:
Traceback (most recent call last):
  File "C:\Users\lpy\AppData\Local\Programs\Python\Python39\lib\threading.py", line 973, in _bootstrap_inner
    self.run()
  File "C:\Users\lpy\AppData\Local\Programs\Python\Python39\lib\threading.py", line 910, in run
    self._target(*self._args, **self._kwargs)
  File "C:\Users\lpy\Desktop\bilibili-api\general.py", line 618, in _
    cmd = download_1(i)
  File "C:\Users\lpy\Desktop\bilibili-api\general.py", line 604, in download_1
    P = download_video(bv, self.header, path=setting["path"])
  File "C:\Users\lpy\Desktop\bilibili-api\module\func.py", line 502, in download_video
    s.set.append({"bv": bv, "byheader": {"user-agent": headers["user-agent"], "cookie": headers["cookie"][1, 20]+"..."}, "path": path})
AttributeError: 'dict' object has no attribute 'append'
Exception in thread Thread-4:
Traceback (most recent call last):
  File "C:\Users\lpy\AppData\Local\Programs\Python\Python39\lib\threading.py", line 973, in _bootstrap_inner
    self.run()
  File "C:\Users\lpy\AppData\Local\Programs\Python\Python39\lib\threading.py", line 910, in run
    self._target(*self._args, **self._kwargs)
  File "C:\Users\lpy\Desktop\bilibili-api\general.py", line 618, in _
    cmd = download_1(i)
  File "C:\Users\lpy\Desktop\bilibili-api\general.py", line 604, in download_1
    P = download_video(bv, self.header, path=setting["path"])
  File "C:\Users\lpy\Desktop\bilibili-api\module\func.py", line 502, in download_video
    s.set.append({"bv": bv, "byheader": {"user-agent": headers["user-agent"], "cookie": headers["cookie"][1, 20]+"..."}, "path": path})
AttributeError: 'dict' object has no attribute 'append'
Exception in thread Thread-5:
Traceback (most recent call last):
  File "C:\Users\lpy\AppData\Local\Programs\Python\Python39\lib\threading.py", line 973, in _bootstrap_inner
    self.run()
  File "C:\Users\lpy\AppData\Local\Programs\Python\Python39\lib\threading.py", line 910, in run
    self._target(*self._args, **self._kwargs)
  File "C:\Users\lpy\Desktop\bilibili-api\general.py", line 618, in _
    cmd = download_1(i)
  File "C:\Users\lpy\Desktop\bilibili-api\general.py", line 604, in download_1
    P = download_video(bv, self.header, path=setting["path"])
  File "C:\Users\lpy\Desktop\bilibili-api\module\func.py", line 502, in download_video
    s.set.append({"bv": bv, "byheader": {"user-agent": headers["user-agent"], "cookie": headers["cookie"][1, 20]+"..."}, "path": path})
AttributeError: 'dict' object has no attribute 'append'
Exception in thread Thread-6:
Traceback (most recent call last):
  File "C:\Users\lpy\AppData\Local\Programs\Python\Python39\lib\threading.py", line 973, in _bootstrap_inner
    self.run()
  File "C:\Users\lpy\AppData\Local\Programs\Python\Python39\lib\threading.py", line 910, in run
    self._target(*self._args, **self._kwargs)
  File "C:\Users\lpy\Desktop\bilibili-api\general.py", line 618, in _
    cmd = download_1(i)
  File "C:\Users\lpy\Desktop\bilibili-api\general.py", line 604, in download_1
    P = download_video(bv, self.header, path=setting["path"])
  File "C:\Users\lpy\Desktop\bilibili-api\module\func.py", line 502, in download_video
    s.set.append({"bv": bv, "byheader": {"user-agent": headers["user-agent"], "cookie": headers["cookie"][1, 20]+"..."}, "path": path})
AttributeError: 'dict' object has no attribute 'append'
Exception in thread Thread-7:
Traceback (most recent call last):
  File "C:\Users\lpy\AppData\Local\Programs\Python\Python39\lib\threading.py", line 973, in _bootstrap_inner
    self.run()
  File "C:\Users\lpy\AppData\Local\Programs\Python\Python39\lib\threading.py", line 910, in run
    self._target(*self._args, **self._kwargs)
  File "C:\Users\lpy\Desktop\bilibili-api\general.py", line 618, in _
    cmd = download_1(i)
  File "C:\Users\lpy\Desktop\bilibili-api\general.py", line 604, in download_1
    P = download_video(bv, self.header, path=setting["path"])
  File "C:\Users\lpy\Desktop\bilibili-api\module\func.py", line 502, in download_video
    s.set.append({"bv": bv, "byheader": {"user-agent": headers["user-agent"], "cookie": headers["cookie"][1, 20]+"..."}, "path": path})
AttributeError: 'dict' object has no attribute 'append'
Exception in thread Thread-8:
Traceback (most recent call last):
  File "C:\Users\lpy\AppData\Local\Programs\Python\Python39\lib\threading.py", line 973, in _bootstrap_inner
    self.run()
  File "C:\Users\lpy\AppData\Local\Programs\Python\Python39\lib\threading.py", line 910, in run
    self._target(*self._args, **self._kwargs)
  File "C:\Users\lpy\Desktop\bilibili-api\general.py", line 618, in _
    cmd = download_1(i)
  File "C:\Users\lpy\Desktop\bilibili-api\general.py", line 604, in download_1
    P = download_video(bv, self.header, path=setting["path"])
  File "C:\Users\lpy\Desktop\bilibili-api\module\func.py", line 502, in download_video
    s.set.append({"bv": bv, "byheader": {"user-agent": headers["user-agent"], "cookie": headers["cookie"][1, 20]+"..."}, "path": path})
AttributeError: 'dict' object has no attribute 'append'
Exception in thread Thread-9:
Traceback (most recent call last):
  File "C:\Users\lpy\AppData\Local\Programs\Python\Python39\lib\threading.py", line 973, in _bootstrap_inner
    self.run()
  File "C:\Users\lpy\AppData\Local\Programs\Python\Python39\lib\threading.py", line 910, in run
    self._target(*self._args, **self._kwargs)
  File "C:\Users\lpy\Desktop\bilibili-api\general.py", line 618, in _
    cmd = download_1(i)
  File "C:\Users\lpy\Desktop\bilibili-api\general.py", line 604, in download_1
    P = download_video(bv, self.header, path=setting["path"])
  File "C:\Users\lpy\Desktop\bilibili-api\module\func.py", line 502, in download_video
    s.set.append({"bv": bv, "byheader": {"user-agent": headers["user-agent"], "cookie": headers["cookie"][1, 20]+"..."}, "path": path})
AttributeError: 'dict' object has no attribute 'append'
Exception in thread Thread-2:
Traceback (most recent call last):
  File "C:\Users\lpy\AppData\Local\Programs\Python\Python39\lib\threading.py", line 973, in _bootstrap_inner
    self.run()
  File "C:\Users\lpy\AppData\Local\Programs\Python\Python39\lib\threading.py", line 910, in run
    self._target(*self._args, **self._kwargs)
  File "C:\Users\lpy\Desktop\bilibili-api\general.py", line 618, in _
    cmd = download_1(i)
  File "C:\Users\lpy\Desktop\bilibili-api\general.py", line 604, in download_1
    P = download_video(bv, self.header, path=setting["path"])
  File "C:\Users\lpy\Desktop\bilibili-api\module\func.py", line 504, in download_video
    s.set.append({"bv": bv, "byheader": {"user-agent": headers["user-agent"], "cookie": headers["cookie"][1, 20]+"..."}, "path": path})
AttributeError: 'dict' object has no attribute 'append'
Exception in thread Thread-3:
Traceback (most recent call last):
  File "C:\Users\lpy\AppData\Local\Programs\Python\Python39\lib\threading.py", line 973, in _bootstrap_inner
    self.run()
  File "C:\Users\lpy\AppData\Local\Programs\Python\Python39\lib\threading.py", line 910, in run
    self._target(*self._args, **self._kwargs)
  File "C:\Users\lpy\Desktop\bilibili-api\general.py", line 618, in _
    cmd = download_1(i)
  File "C:\Users\lpy\Desktop\bilibili-api\general.py", line 604, in download_1
    P = download_video(bv, self.header, path=setting["path"])
  File "C:\Users\lpy\Desktop\bilibili-api\module\func.py", line 504, in download_video
    s.set.append({"bv": bv, "byheader": {"user-agent": headers["user-agent"], "cookie": headers["cookie"][1, 20]+"..."}, "path": path})
AttributeError: 'dict' object has no attribute 'append'
Exception in thread Thread-4:
Traceback (most recent call last):
  File "C:\Users\lpy\AppData\Local\Programs\Python\Python39\lib\threading.py", line 973, in _bootstrap_inner
    self.run()
  File "C:\Users\lpy\AppData\Local\Programs\Python\Python39\lib\threading.py", line 910, in run
    self._target(*self._args, **self._kwargs)
  File "C:\Users\lpy\Desktop\bilibili-api\general.py", line 618, in _
    cmd = download_1(i)
  File "C:\Users\lpy\Desktop\bilibili-api\general.py", line 604, in download_1
    P = download_video(bv, self.header, path=setting["path"])
  File "C:\Users\lpy\Desktop\bilibili-api\module\func.py", line 504, in download_video
    s.set.append({"bv": bv, "byheader": {"user-agent": headers["user-agent"], "cookie": headers["cookie"][1, 20]+"..."}, "path": path})
AttributeError: 'dict' object has no attribute 'append'
Exception in thread Thread-5:
Traceback (most recent call last):
  File "C:\Users\lpy\AppData\Local\Programs\Python\Python39\lib\threading.py", line 973, in _bootstrap_inner
    self.run()
  File "C:\Users\lpy\AppData\Local\Programs\Python\Python39\lib\threading.py", line 910, in run
    self._target(*self._args, **self._kwargs)
  File "C:\Users\lpy\Desktop\bilibili-api\general.py", line 618, in _
    cmd = download_1(i)
  File "C:\Users\lpy\Desktop\bilibili-api\general.py", line 604, in download_1
    P = download_video(bv, self.header, path=setting["path"])
  File "C:\Users\lpy\Desktop\bilibili-api\module\func.py", line 504, in download_video
    s.set.append({"bv": bv, "byheader": {"user-agent": headers["user-agent"], "cookie": headers["cookie"][1, 20]+"..."}, "path": path})
AttributeError: 'dict' object has no attribute 'append'
Exception in thread Thread-6:
Traceback (most recent call last):
  File "C:\Users\lpy\AppData\Local\Programs\Python\Python39\lib\threading.py", line 973, in _bootstrap_inner
    self.run()
  File "C:\Users\lpy\AppData\Local\Programs\Python\Python39\lib\threading.py", line 910, in run
    self._target(*self._args, **self._kwargs)
  File "C:\Users\lpy\Desktop\bilibili-api\general.py", line 618, in _
    cmd = download_1(i)
  File "C:\Users\lpy\Desktop\bilibili-api\general.py", line 604, in download_1
    P = download_video(bv, self.header, path=setting["path"])
  File "C:\Users\lpy\Desktop\bilibili-api\module\func.py", line 504, in download_video
    s.set.append({"bv": bv, "byheader": {"user-agent": headers["user-agent"], "cookie": headers["cookie"][1, 20]+"..."}, "path": path})
AttributeError: 'dict' object has no attribute 'append'
Exception in thread Thread-7:
Traceback (most recent call last):
  File "C:\Users\lpy\AppData\Local\Programs\Python\Python39\lib\threading.py", line 973, in _bootstrap_inner
    self.run()
  File "C:\Users\lpy\AppData\Local\Programs\Python\Python39\lib\threading.py", line 910, in run
    self._target(*self._args, **self._kwargs)
  File "C:\Users\lpy\Desktop\bilibili-api\general.py", line 618, in _
    cmd = download_1(i)
  File "C:\Users\lpy\Desktop\bilibili-api\general.py", line 604, in download_1
    P = download_video(bv, self.header, path=setting["path"])
  File "C:\Users\lpy\Desktop\bilibili-api\module\func.py", line 504, in download_video
    s.set.append({"bv": bv, "byheader": {"user-agent": headers["user-agent"], "cookie": headers["cookie"][1, 20]+"..."}, "path": path})
AttributeError: 'dict' object has no attribute 'append'
Exception in thread Thread-2:
Traceback (most recent call last):
  File "C:\Users\lpy\.virtualenvs\bilibili-api--AVx_MxI\lib\site-packages\urllib3\connectionpool.py", line 700, in urlopen
    self._prepare_proxy(conn)
  File "C:\Users\lpy\.virtualenvs\bilibili-api--AVx_MxI\lib\site-packages\urllib3\connectionpool.py", line 996, in _prepare_proxy
    conn.connect()
  File "C:\Users\lpy\.virtualenvs\bilibili-api--AVx_MxI\lib\site-packages\urllib3\connection.py", line 364, in connect
    self.sock = conn = self._connect_tls_proxy(hostname, conn)
  File "C:\Users\lpy\.virtualenvs\bilibili-api--AVx_MxI\lib\site-packages\urllib3\connection.py", line 499, in _connect_tls_proxy
    socket = ssl_wrap_socket(
  File "C:\Users\lpy\.virtualenvs\bilibili-api--AVx_MxI\lib\site-packages\urllib3\util\ssl_.py", line 453, in ssl_wrap_socket
    ssl_sock = _ssl_wrap_socket_impl(sock, context, tls_in_tls)
  File "C:\Users\lpy\.virtualenvs\bilibili-api--AVx_MxI\lib\site-packages\urllib3\util\ssl_.py", line 495, in _ssl_wrap_socket_impl
    return ssl_context.wrap_socket(sock)
  File "C:\Users\lpy\AppData\Local\Programs\Python\Python39\lib\ssl.py", line 500, in wrap_socket
    return self.sslsocket_class._create(
  File "C:\Users\lpy\AppData\Local\Programs\Python\Python39\lib\ssl.py", line 1040, in _create
    self.do_handshake()
  File "C:\Users\lpy\AppData\Local\Programs\Python\Python39\lib\ssl.py", line 1309, in do_handshake
    self._sslobj.do_handshake()
ssl.SSLEOFError: EOF occurred in violation of protocol (_ssl.c:1129)

During handling of the above exception, another exception occurred:

Traceback (most recent call last):
  File "C:\Users\lpy\.virtualenvs\bilibili-api--AVx_MxI\lib\site-packages\requests\adapters.py", line 489, in send
    resp = conn.urlopen(
  File "C:\Users\lpy\.virtualenvs\bilibili-api--AVx_MxI\lib\site-packages\urllib3\connectionpool.py", line 787, in urlopen
    retries = retries.increment(
  File "C:\Users\lpy\.virtualenvs\bilibili-api--AVx_MxI\lib\site-packages\urllib3\util\retry.py", line 592, in increment
    raise MaxRetryError(_pool, url, error or ResponseError(cause))
urllib3.exceptions.MaxRetryError: HTTPSConnectionPool(host='api.bilibili.com', port=443): Max retries exceeded with url: /x/web-interface/nav (Caused by SSLError(SSLEOFError(8, 'EOF occurred in violation of protocol (_ssl.c:1129)')))

During handling of the above exception, another exception occurred:

Traceback (most recent call last):
  File "C:\Users\lpy\AppData\Local\Programs\Python\Python39\lib\threading.py", line 973, in _bootstrap_inner
    self.run()
  File "C:\Users\lpy\AppData\Local\Programs\Python\Python39\lib\threading.py", line 910, in run
    self._target(*self._args, **self._kwargs)
  File "C:\Users\lpy\Desktop\bilibili-api\general.py", line 528, in a_
    self.usrJsonObj = get_user_info(headers=self.header)
  File "C:\Users\lpy\Desktop\bilibili-api\module\func.py", line 359, in get_user_info
    response = requests.get(url, headers=headers, timeout=10)
  File "C:\Users\lpy\.virtualenvs\bilibili-api--AVx_MxI\lib\site-packages\requests\api.py", line 73, in get
    return request("get", url, params=params, **kwargs)
  File "C:\Users\lpy\.virtualenvs\bilibili-api--AVx_MxI\lib\site-packages\requests\api.py", line 59, in request
    return session.request(method=method, url=url, **kwargs)
  File "C:\Users\lpy\.virtualenvs\bilibili-api--AVx_MxI\lib\site-packages\requests\sessions.py", line 587, in request
    resp = self.send(prep, **send_kwargs)
  File "C:\Users\lpy\.virtualenvs\bilibili-api--AVx_MxI\lib\site-packages\requests\sessions.py", line 701, in send
    r = adapter.send(request, **kwargs)
  File "C:\Users\lpy\.virtualenvs\bilibili-api--AVx_MxI\lib\site-packages\requests\adapters.py", line 563, in send
    raise SSLError(e, request=request)
requests.exceptions.SSLError: HTTPSConnectionPool(host='api.bilibili.com', port=443): Max retries exceeded with url: /x/web-interface/nav (Caused by SSLError(SSLEOFError(8, 'EOF occurred in violation of protocol (_ssl.c:1129)')))
Exception in thread Thread-5:
Traceback (most recent call last):
  File "C:\Users\lpy\AppData\Local\Programs\Python\Python39\lib\threading.py", line 973, in _bootstrap_inner
    self.run()
  File "C:\Users\lpy\AppData\Local\Programs\Python\Python39\lib\threading.py", line 910, in run
    self._target(*self._args, **self._kwargs)
  File "C:\Users\lpy\Desktop\bilibili-api\general.py", line 618, in _
    cmd = download_1(i)
  File "C:\Users\lpy\Desktop\bilibili-api\general.py", line 604, in download_1
    P = download_video(bv, self.header, path=setting["path"])
  File "C:\Users\lpy\Desktop\bilibili-api\module\func.py", line 504, in download_video
    s.set.append({"bv": bv, "byheader": {"user-agent": headers["user-agent"], "cookie": headers["cookie"][1, 20]+"..."}, "path": path})
AttributeError: 'dict' object has no attribute 'append'
Exception in thread Thread-7:
Traceback (most recent call last):
  File "C:\Users\lpy\AppData\Local\Programs\Python\Python39\lib\threading.py", line 973, in _bootstrap_inner
    self.run()
  File "C:\Users\lpy\AppData\Local\Programs\Python\Python39\lib\threading.py", line 910, in run
    self._target(*self._args, **self._kwargs)
  File "C:\Users\lpy\Desktop\bilibili-api\general.py", line 618, in _
    cmd = download_1(i)
  File "C:\Users\lpy\Desktop\bilibili-api\general.py", line 604, in download_1
    P = download_video(bv, self.header, path=setting["path"])
  File "C:\Users\lpy\Desktop\bilibili-api\module\func.py", line 504, in download_video
    s.set.append({"bv": bv, "byheader": {"user-agent": headers["user-agent"], "cookie": headers["cookie"][1, 20]+"..."}, "path": path})
AttributeError: 'dict' object has no attribute 'append'
Exception in thread Thread-8:
Traceback (most recent call last):
  File "C:\Users\lpy\AppData\Local\Programs\Python\Python39\lib\threading.py", line 973, in _bootstrap_inner
    self.run()
  File "C:\Users\lpy\AppData\Local\Programs\Python\Python39\lib\threading.py", line 910, in run
    self._target(*self._args, **self._kwargs)
  File "C:\Users\lpy\Desktop\bilibili-api\general.py", line 618, in _
    cmd = download_1(i)
  File "C:\Users\lpy\Desktop\bilibili-api\general.py", line 604, in download_1
    P = download_video(bv, self.header, path=setting["path"])
  File "C:\Users\lpy\Desktop\bilibili-api\module\func.py", line 504, in download_video
    s.set.append({"bv": bv, "byheader": {"user-agent": headers["user-agent"], "cookie": headers["cookie"][1, 20]+"..."}, "path": path})
AttributeError: 'dict' object has no attribute 'append'
Exception in thread Thread-9:
Traceback (most recent call last):
  File "C:\Users\lpy\AppData\Local\Programs\Python\Python39\lib\threading.py", line 973, in _bootstrap_inner
    self.run()
  File "C:\Users\lpy\AppData\Local\Programs\Python\Python39\lib\threading.py", line 910, in run
    self._target(*self._args, **self._kwargs)
  File "C:\Users\lpy\Desktop\bilibili-api\general.py", line 618, in _
    cmd = download_1(i)
  File "C:\Users\lpy\Desktop\bilibili-api\general.py", line 604, in download_1
    P = download_video(bv, self.header, path=setting["path"])
  File "C:\Users\lpy\Desktop\bilibili-api\module\func.py", line 504, in download_video
    s.set.append({"bv": bv, "byheader": {"user-agent": headers["user-agent"], "cookie": headers["cookie"][1, 20]+"..."}, "path": path})
AttributeError: 'dict' object has no attribute 'append'
Exception in thread Thread-10:
Traceback (most recent call last):
  File "C:\Users\lpy\AppData\Local\Programs\Python\Python39\lib\threading.py", line 973, in _bootstrap_inner
    self.run()
  File "C:\Users\lpy\AppData\Local\Programs\Python\Python39\lib\threading.py", line 910, in run
    self._target(*self._args, **self._kwargs)
  File "C:\Users\lpy\Desktop\bilibili-api\general.py", line 618, in _
    cmd = download_1(i)
  File "C:\Users\lpy\Desktop\bilibili-api\general.py", line 604, in download_1
    P = download_video(bv, self.header, path=setting["path"])
  File "C:\Users\lpy\Desktop\bilibili-api\module\func.py", line 504, in download_video
    s.set.append({"bv": bv, "byheader": {"user-agent": headers["user-agent"], "cookie": headers["cookie"][1, 20]+"..."}, "path": path})
AttributeError: 'dict' object has no attribute 'append'
Exception in thread Thread-11:
Traceback (most recent call last):
  File "C:\Users\lpy\AppData\Local\Programs\Python\Python39\lib\threading.py", line 973, in _bootstrap_inner
    self.run()
  File "C:\Users\lpy\AppData\Local\Programs\Python\Python39\lib\threading.py", line 910, in run
    self._target(*self._args, **self._kwargs)
  File "C:\Users\lpy\Desktop\bilibili-api\general.py", line 618, in _
    cmd = download_1(i)
  File "C:\Users\lpy\Desktop\bilibili-api\general.py", line 604, in download_1
    P = download_video(bv, self.header, path=setting["path"])
  File "C:\Users\lpy\Desktop\bilibili-api\module\func.py", line 504, in download_video
    # s.set.append({"bv": bv, "byheader": {"user-agent": headers["user-agent"], "cookie": headers["cookie"][1, 20]+"..."}, "path": path})
AttributeError: 'dict' object has no attribute 'append'
Exception in thread Thread-16:
Traceback (most recent call last):
  File "C:\Users\lpy\AppData\Local\Programs\Python\Python39\lib\threading.py", line 973, in _bootstrap_inner
    self.run()
  File "C:\Users\lpy\AppData\Local\Programs\Python\Python39\lib\threading.py", line 910, in run
    self._target(*self._args, **self._kwargs)
  File "C:\Users\lpy\Desktop\bilibili-api\general.py", line 618, in _
    cmd = download_1(i)
  File "C:\Users\lpy\Desktop\bilibili-api\general.py", line 604, in download_1
    P = download_video(bv, self.header, path=setting["path"])
  File "C:\Users\lpy\Desktop\bilibili-api\module\func.py", line 504, in download_video
    # s.set.append({"bv": bv, "byheader": {"user-agent": headers["user-agent"], "cookie": headers["cookie"][1, 20]+"..."}, "path": path})
AttributeError: 'dict' object has no attribute 'append'
Exception in thread Thread-17:
Traceback (most recent call last):
  File "C:\Users\lpy\AppData\Local\Programs\Python\Python39\lib\threading.py", line 973, in _bootstrap_inner
    self.run()
  File "C:\Users\lpy\AppData\Local\Programs\Python\Python39\lib\threading.py", line 910, in run
    self._target(*self._args, **self._kwargs)
  File "C:\Users\lpy\Desktop\bilibili-api\general.py", line 618, in _
    cmd = download_1(i)
  File "C:\Users\lpy\Desktop\bilibili-api\general.py", line 604, in download_1
    P = download_video(bv, self.header, path=setting["path"])
  File "C:\Users\lpy\Desktop\bilibili-api\module\func.py", line 504, in download_video
    # s.set.append({"bv": bv, "byheader": {"user-agent": headers["user-agent"], "cookie": headers["cookie"][1, 20]+"..."}, "path": path})
AttributeError: 'dict' object has no attribute 'append'
Exception in thread Thread-18:
Traceback (most recent call last):
  File "C:\Users\lpy\AppData\Local\Programs\Python\Python39\lib\threading.py", line 973, in _bootstrap_inner
    self.run()
  File "C:\Users\lpy\AppData\Local\Programs\Python\Python39\lib\threading.py", line 910, in run
    self._target(*self._args, **self._kwargs)
  File "C:\Users\lpy\Desktop\bilibili-api\general.py", line 618, in _
    cmd = download_1(i)
  File "C:\Users\lpy\Desktop\bilibili-api\general.py", line 604, in download_1
    P = download_video(bv, self.header, path=setting["path"])
  File "C:\Users\lpy\Desktop\bilibili-api\module\func.py", line 504, in download_video
    # s.set.append({"bv": bv, "byheader": {"user-agent": headers["user-agent"], "cookie": headers["cookie"][1, 20]+"..."}, "path": path})
AttributeError: 'dict' object has no attribute 'append'
Traceback (most recent call last):
  File "general.py", line 601, in d
    def d(self) -> None:  # download file
KeyboardInterrupt
Exception in thread Thread-2:
Traceback (most recent call last):
  File "C:\Users\lpy\.virtualenvs\bilibili-api--AVx_MxI\lib\site-packages\urllib3\connectionpool.py", line 700, in urlopen
    self._prepare_proxy(conn)
  File "C:\Users\lpy\.virtualenvs\bilibili-api--AVx_MxI\lib\site-packages\urllib3\connectionpool.py", line 996, in _prepare_proxy
    conn.connect()
  File "C:\Users\lpy\.virtualenvs\bilibili-api--AVx_MxI\lib\site-packages\urllib3\connection.py", line 364, in connect
    self.sock = conn = self._connect_tls_proxy(hostname, conn)
  File "C:\Users\lpy\.virtualenvs\bilibili-api--AVx_MxI\lib\site-packages\urllib3\connection.py", line 499, in _connect_tls_proxy
    socket = ssl_wrap_socket(
  File "C:\Users\lpy\.virtualenvs\bilibili-api--AVx_MxI\lib\site-packages\urllib3\util\ssl_.py", line 453, in ssl_wrap_socket
    ssl_sock = _ssl_wrap_socket_impl(sock, context, tls_in_tls)
  File "C:\Users\lpy\.virtualenvs\bilibili-api--AVx_MxI\lib\site-packages\urllib3\util\ssl_.py", line 495, in _ssl_wrap_socket_impl
    return ssl_context.wrap_socket(sock)
  File "C:\Users\lpy\AppData\Local\Programs\Python\Python39\lib\ssl.py", line 500, in wrap_socket
    return self.sslsocket_class._create(
  File "C:\Users\lpy\AppData\Local\Programs\Python\Python39\lib\ssl.py", line 1040, in _create
    self.do_handshake()
  File "C:\Users\lpy\AppData\Local\Programs\Python\Python39\lib\ssl.py", line 1309, in do_handshake
    self._sslobj.do_handshake()
ssl.SSLEOFError: EOF occurred in violation of protocol (_ssl.c:1129)

During handling of the above exception, another exception occurred:

Traceback (most recent call last):
  File "C:\Users\lpy\.virtualenvs\bilibili-api--AVx_MxI\lib\site-packages\requests\adapters.py", line 489, in send
    resp = conn.urlopen(
  File "C:\Users\lpy\.virtualenvs\bilibili-api--AVx_MxI\lib\site-packages\urllib3\connectionpool.py", line 787, in urlopen
    retries = retries.increment(
  File "C:\Users\lpy\.virtualenvs\bilibili-api--AVx_MxI\lib\site-packages\urllib3\util\retry.py", line 592, in increment
    raise MaxRetryError(_pool, url, error or ResponseError(cause))
urllib3.exceptions.MaxRetryError: HTTPSConnectionPool(host='api.bilibili.com', port=443): Max retries exceeded with url: /x/web-interface/nav (Caused by SSLError(SSLEOFError(8, 'EOF occurred in violation of protocol (_ssl.c:1129)')))

During handling of the above exception, another exception occurred:

Traceback (most recent call last):
  File "C:\Users\lpy\AppData\Local\Programs\Python\Python39\lib\threading.py", line 973, in _bootstrap_inner
    self.run()
  File "C:\Users\lpy\AppData\Local\Programs\Python\Python39\lib\threading.py", line 910, in run
    self._target(*self._args, **self._kwargs)
  File "C:\Users\lpy\Desktop\bilibili-api\general.py", line 528, in a_
    self.usrJsonObj = get_user_info(headers=self.header)
  File "C:\Users\lpy\Desktop\bilibili-api\module\func.py", line 359, in get_user_info
    response = requests.get(url, headers=headers, timeout=10)
  File "C:\Users\lpy\.virtualenvs\bilibili-api--AVx_MxI\lib\site-packages\requests\api.py", line 73, in get
    return request("get", url, params=params, **kwargs)
  File "C:\Users\lpy\.virtualenvs\bilibili-api--AVx_MxI\lib\site-packages\requests\api.py", line 59, in request
    return session.request(method=method, url=url, **kwargs)
  File "C:\Users\lpy\.virtualenvs\bilibili-api--AVx_MxI\lib\site-packages\requests\sessions.py", line 587, in request
    resp = self.send(prep, **send_kwargs)
  File "C:\Users\lpy\.virtualenvs\bilibili-api--AVx_MxI\lib\site-packages\requests\sessions.py", line 701, in send
    r = adapter.send(request, **kwargs)
  File "C:\Users\lpy\.virtualenvs\bilibili-api--AVx_MxI\lib\site-packages\requests\adapters.py", line 563, in send
    raise SSLError(e, request=request)
requests.exceptions.SSLError: HTTPSConnectionPool(host='api.bilibili.com', port=443): Max retries exceeded with url: /x/web-interface/nav (Caused by SSLError(SSLEOFError(8, 'EOF occurred in violation of protocol (_ssl.c:1129)')))
Exception in thread Thread-3:
Traceback (most recent call last):
  File "C:\Users\lpy\.virtualenvs\bilibili-api--AVx_MxI\lib\site-packages\urllib3\connectionpool.py", line 700, in urlopen
    self._prepare_proxy(conn)
  File "C:\Users\lpy\.virtualenvs\bilibili-api--AVx_MxI\lib\site-packages\urllib3\connectionpool.py", line 996, in _prepare_proxy
    conn.connect()
  File "C:\Users\lpy\.virtualenvs\bilibili-api--AVx_MxI\lib\site-packages\urllib3\connection.py", line 364, in connect
    self.sock = conn = self._connect_tls_proxy(hostname, conn)
  File "C:\Users\lpy\.virtualenvs\bilibili-api--AVx_MxI\lib\site-packages\urllib3\connection.py", line 499, in _connect_tls_proxy
    socket = ssl_wrap_socket(
  File "C:\Users\lpy\.virtualenvs\bilibili-api--AVx_MxI\lib\site-packages\urllib3\util\ssl_.py", line 453, in ssl_wrap_socket
    ssl_sock = _ssl_wrap_socket_impl(sock, context, tls_in_tls)
  File "C:\Users\lpy\.virtualenvs\bilibili-api--AVx_MxI\lib\site-packages\urllib3\util\ssl_.py", line 495, in _ssl_wrap_socket_impl
    return ssl_context.wrap_socket(sock)
  File "C:\Users\lpy\AppData\Local\Programs\Python\Python39\lib\ssl.py", line 500, in wrap_socket
    return self.sslsocket_class._create(
  File "C:\Users\lpy\AppData\Local\Programs\Python\Python39\lib\ssl.py", line 1040, in _create
    self.do_handshake()
  File "C:\Users\lpy\AppData\Local\Programs\Python\Python39\lib\ssl.py", line 1309, in do_handshake
    self._sslobj.do_handshake()
ssl.SSLEOFError: EOF occurred in violation of protocol (_ssl.c:1129)

During handling of the above exception, another exception occurred:

Traceback (most recent call last):
  File "C:\Users\lpy\.virtualenvs\bilibili-api--AVx_MxI\lib\site-packages\requests\adapters.py", line 489, in send
    resp = conn.urlopen(
  File "C:\Users\lpy\.virtualenvs\bilibili-api--AVx_MxI\lib\site-packages\urllib3\connectionpool.py", line 787, in urlopen
    retries = retries.increment(
  File "C:\Users\lpy\.virtualenvs\bilibili-api--AVx_MxI\lib\site-packages\urllib3\util\retry.py", line 592, in increment
    raise MaxRetryError(_pool, url, error or ResponseError(cause))
urllib3.exceptions.MaxRetryError: HTTPSConnectionPool(host='api.bilibili.com', port=443): Max retries exceeded with url: /x/web-interface/nav (Caused by SSLError(SSLEOFError(8, 'EOF occurred in violation of protocol (_ssl.c:1129)')))

During handling of the above exception, another exception occurred:

Traceback (most recent call last):
  File "C:\Users\lpy\AppData\Local\Programs\Python\Python39\lib\threading.py", line 973, in _bootstrap_inner
    self.run()
  File "C:\Users\lpy\AppData\Local\Programs\Python\Python39\lib\threading.py", line 910, in run
    self._target(*self._args, **self._kwargs)
  File "C:\Users\lpy\Desktop\bilibili-api\general.py", line 528, in a_
    self.usrJsonObj = get_user_info(headers=self.header)
  File "C:\Users\lpy\Desktop\bilibili-api\module\func.py", line 359, in get_user_info
    response = requests.get(url, headers=headers, timeout=10)
  File "C:\Users\lpy\.virtualenvs\bilibili-api--AVx_MxI\lib\site-packages\requests\api.py", line 73, in get
    return request("get", url, params=params, **kwargs)
  File "C:\Users\lpy\.virtualenvs\bilibili-api--AVx_MxI\lib\site-packages\requests\api.py", line 59, in request
    return session.request(method=method, url=url, **kwargs)
  File "C:\Users\lpy\.virtualenvs\bilibili-api--AVx_MxI\lib\site-packages\requests\sessions.py", line 587, in request
    resp = self.send(prep, **send_kwargs)
  File "C:\Users\lpy\.virtualenvs\bilibili-api--AVx_MxI\lib\site-packages\requests\sessions.py", line 701, in send
    r = adapter.send(request, **kwargs)
  File "C:\Users\lpy\.virtualenvs\bilibili-api--AVx_MxI\lib\site-packages\requests\adapters.py", line 563, in send
    raise SSLError(e, request=request)
requests.exceptions.SSLError: HTTPSConnectionPool(host='api.bilibili.com', port=443): Max retries exceeded with url: /x/web-interface/nav (Caused by SSLError(SSLEOFError(8, 'EOF occurred in violation of protocol (_ssl.c:1129)')))
Exception in thread Thread-2:
Traceback (most recent call last):
  File "C:\Users\lpy\.virtualenvs\bilibili-api--AVx_MxI\lib\site-packages\urllib3\connectionpool.py", line 700, in urlopen
    self._prepare_proxy(conn)
  File "C:\Users\lpy\.virtualenvs\bilibili-api--AVx_MxI\lib\site-packages\urllib3\connectionpool.py", line 996, in _prepare_proxy
    conn.connect()
  File "C:\Users\lpy\.virtualenvs\bilibili-api--AVx_MxI\lib\site-packages\urllib3\connection.py", line 364, in connect
    self.sock = conn = self._connect_tls_proxy(hostname, conn)
  File "C:\Users\lpy\.virtualenvs\bilibili-api--AVx_MxI\lib\site-packages\urllib3\connection.py", line 499, in _connect_tls_proxy
    socket = ssl_wrap_socket(
  File "C:\Users\lpy\.virtualenvs\bilibili-api--AVx_MxI\lib\site-packages\urllib3\util\ssl_.py", line 453, in ssl_wrap_socket
    ssl_sock = _ssl_wrap_socket_impl(sock, context, tls_in_tls)
  File "C:\Users\lpy\.virtualenvs\bilibili-api--AVx_MxI\lib\site-packages\urllib3\util\ssl_.py", line 495, in _ssl_wrap_socket_impl
    return ssl_context.wrap_socket(sock)
  File "C:\Users\lpy\AppData\Local\Programs\Python\Python39\lib\ssl.py", line 500, in wrap_socket
    return self.sslsocket_class._create(
  File "C:\Users\lpy\AppData\Local\Programs\Python\Python39\lib\ssl.py", line 1040, in _create
    self.do_handshake()
  File "C:\Users\lpy\AppData\Local\Programs\Python\Python39\lib\ssl.py", line 1309, in do_handshake
    self._sslobj.do_handshake()
ssl.SSLEOFError: EOF occurred in violation of protocol (_ssl.c:1129)

During handling of the above exception, another exception occurred:

Traceback (most recent call last):
  File "C:\Users\lpy\.virtualenvs\bilibili-api--AVx_MxI\lib\site-packages\requests\adapters.py", line 489, in send
    resp = conn.urlopen(
  File "C:\Users\lpy\.virtualenvs\bilibili-api--AVx_MxI\lib\site-packages\urllib3\connectionpool.py", line 787, in urlopen
    retries = retries.increment(
  File "C:\Users\lpy\.virtualenvs\bilibili-api--AVx_MxI\lib\site-packages\urllib3\util\retry.py", line 592, in increment
    raise MaxRetryError(_pool, url, error or ResponseError(cause))
urllib3.exceptions.MaxRetryError: HTTPSConnectionPool(host='api.bilibili.com', port=443): Max retries exceeded with url: /x/web-interface/nav (Caused by SSLError(SSLEOFError(8, 'EOF occurred in violation of protocol (_ssl.c:1129)')))

During handling of the above exception, another exception occurred:

Traceback (most recent call last):
  File "C:\Users\lpy\AppData\Local\Programs\Python\Python39\lib\threading.py", line 973, in _bootstrap_inner
    self.run()
  File "C:\Users\lpy\AppData\Local\Programs\Python\Python39\lib\threading.py", line 910, in run
    self._target(*self._args, **self._kwargs)
  File "C:\Users\lpy\Desktop\bilibili-api\general.py", line 528, in a_
    self.usrJsonObj = get_user_info(headers=self.header)
  File "C:\Users\lpy\Desktop\bilibili-api\module\func.py", line 359, in get_user_info
    response = requests.get(url, headers=headers, timeout=10)
  File "C:\Users\lpy\.virtualenvs\bilibili-api--AVx_MxI\lib\site-packages\requests\api.py", line 73, in get
    return request("get", url, params=params, **kwargs)
  File "C:\Users\lpy\.virtualenvs\bilibili-api--AVx_MxI\lib\site-packages\requests\api.py", line 59, in request
    return session.request(method=method, url=url, **kwargs)
  File "C:\Users\lpy\.virtualenvs\bilibili-api--AVx_MxI\lib\site-packages\requests\sessions.py", line 587, in request
    resp = self.send(prep, **send_kwargs)
  File "C:\Users\lpy\.virtualenvs\bilibili-api--AVx_MxI\lib\site-packages\requests\sessions.py", line 701, in send
    r = adapter.send(request, **kwargs)
  File "C:\Users\lpy\.virtualenvs\bilibili-api--AVx_MxI\lib\site-packages\requests\adapters.py", line 563, in send
    raise SSLError(e, request=request)
requests.exceptions.SSLError: HTTPSConnectionPool(host='api.bilibili.com', port=443): Max retries exceeded with url: /x/web-interface/nav (Caused by SSLError(SSLEOFError(8, 'EOF occurred in violation of protocol (_ssl.c:1129)')))
Exception in thread Thread-2:
Traceback (most recent call last):
  File "C:\Users\lpy\.virtualenvs\bilibili-api--AVx_MxI\lib\site-packages\urllib3\connectionpool.py", line 700, in urlopen
    self._prepare_proxy(conn)
  File "C:\Users\lpy\.virtualenvs\bilibili-api--AVx_MxI\lib\site-packages\urllib3\connectionpool.py", line 996, in _prepare_proxy
    conn.connect()
  File "C:\Users\lpy\.virtualenvs\bilibili-api--AVx_MxI\lib\site-packages\urllib3\connection.py", line 364, in connect
    self.sock = conn = self._connect_tls_proxy(hostname, conn)
  File "C:\Users\lpy\.virtualenvs\bilibili-api--AVx_MxI\lib\site-packages\urllib3\connection.py", line 499, in _connect_tls_proxy
    socket = ssl_wrap_socket(
  File "C:\Users\lpy\.virtualenvs\bilibili-api--AVx_MxI\lib\site-packages\urllib3\util\ssl_.py", line 453, in ssl_wrap_socket
    ssl_sock = _ssl_wrap_socket_impl(sock, context, tls_in_tls)
  File "C:\Users\lpy\.virtualenvs\bilibili-api--AVx_MxI\lib\site-packages\urllib3\util\ssl_.py", line 495, in _ssl_wrap_socket_impl
    return ssl_context.wrap_socket(sock)
  File "C:\Users\lpy\AppData\Local\Programs\Python\Python39\lib\ssl.py", line 500, in wrap_socket
    return self.sslsocket_class._create(
  File "C:\Users\lpy\AppData\Local\Programs\Python\Python39\lib\ssl.py", line 1040, in _create
    self.do_handshake()
  File "C:\Users\lpy\AppData\Local\Programs\Python\Python39\lib\ssl.py", line 1309, in do_handshake
    self._sslobj.do_handshake()
ssl.SSLEOFError: EOF occurred in violation of protocol (_ssl.c:1129)

During handling of the above exception, another exception occurred:

Traceback (most recent call last):
  File "C:\Users\lpy\.virtualenvs\bilibili-api--AVx_MxI\lib\site-packages\requests\adapters.py", line 489, in send
    resp = conn.urlopen(
  File "C:\Users\lpy\.virtualenvs\bilibili-api--AVx_MxI\lib\site-packages\urllib3\connectionpool.py", line 787, in urlopen
    retries = retries.increment(
  File "C:\Users\lpy\.virtualenvs\bilibili-api--AVx_MxI\lib\site-packages\urllib3\util\retry.py", line 592, in increment
    raise MaxRetryError(_pool, url, error or ResponseError(cause))
urllib3.exceptions.MaxRetryError: HTTPSConnectionPool(host='api.bilibili.com', port=443): Max retries exceeded with url: /x/web-interface/nav (Caused by SSLError(SSLEOFError(8, 'EOF occurred in violation of protocol (_ssl.c:1129)')))

During handling of the above exception, another exception occurred:

Traceback (most recent call last):
  File "C:\Users\lpy\AppData\Local\Programs\Python\Python39\lib\threading.py", line 973, in _bootstrap_inner
    self.run()
  File "C:\Users\lpy\AppData\Local\Programs\Python\Python39\lib\threading.py", line 910, in run
    self._target(*self._args, **self._kwargs)
  File "C:\Users\lpy\Desktop\bilibili-api\general.py", line 528, in a_
    self.usrJsonObj = get_user_info(headers=self.header)
  File "C:\Users\lpy\Desktop\bilibili-api\module\func.py", line 360, in get_user_info
    response = requests.get(url, headers=headers, timeout=10)
  File "C:\Users\lpy\.virtualenvs\bilibili-api--AVx_MxI\lib\site-packages\requests\sessions.py", line 600, in get
    return self.request("GET", url, **kwargs)
  File "C:\Users\lpy\.virtualenvs\bilibili-api--AVx_MxI\lib\site-packages\requests\sessions.py", line 587, in request
    resp = self.send(prep, **send_kwargs)
  File "C:\Users\lpy\.virtualenvs\bilibili-api--AVx_MxI\lib\site-packages\requests\sessions.py", line 701, in send
    r = adapter.send(request, **kwargs)
  File "C:\Users\lpy\.virtualenvs\bilibili-api--AVx_MxI\lib\site-packages\requests\adapters.py", line 563, in send
    raise SSLError(e, request=request)
requests.exceptions.SSLError: HTTPSConnectionPool(host='api.bilibili.com', port=443): Max retries exceeded with url: /x/web-interface/nav (Caused by SSLError(SSLEOFError(8, 'EOF occurred in violation of protocol (_ssl.c:1129)')))
Exception in thread Thread-2:
Traceback (most recent call last):
  File "C:\Users\lpy\.virtualenvs\bilibili-api--AVx_MxI\lib\site-packages\urllib3\connectionpool.py", line 700, in urlopen
    self._prepare_proxy(conn)
  File "C:\Users\lpy\.virtualenvs\bilibili-api--AVx_MxI\lib\site-packages\urllib3\connectionpool.py", line 996, in _prepare_proxy
    conn.connect()
  File "C:\Users\lpy\.virtualenvs\bilibili-api--AVx_MxI\lib\site-packages\urllib3\connection.py", line 364, in connect
    self.sock = conn = self._connect_tls_proxy(hostname, conn)
  File "C:\Users\lpy\.virtualenvs\bilibili-api--AVx_MxI\lib\site-packages\urllib3\connection.py", line 499, in _connect_tls_proxy
    socket = ssl_wrap_socket(
  File "C:\Users\lpy\.virtualenvs\bilibili-api--AVx_MxI\lib\site-packages\urllib3\util\ssl_.py", line 453, in ssl_wrap_socket
    ssl_sock = _ssl_wrap_socket_impl(sock, context, tls_in_tls)
  File "C:\Users\lpy\.virtualenvs\bilibili-api--AVx_MxI\lib\site-packages\urllib3\util\ssl_.py", line 495, in _ssl_wrap_socket_impl
    return ssl_context.wrap_socket(sock)
  File "C:\Users\lpy\AppData\Local\Programs\Python\Python39\lib\ssl.py", line 500, in wrap_socket
    return self.sslsocket_class._create(
  File "C:\Users\lpy\AppData\Local\Programs\Python\Python39\lib\ssl.py", line 1040, in _create
    self.do_handshake()
  File "C:\Users\lpy\AppData\Local\Programs\Python\Python39\lib\ssl.py", line 1309, in do_handshake
    self._sslobj.do_handshake()
ssl.SSLEOFError: EOF occurred in violation of protocol (_ssl.c:1129)

During handling of the above exception, another exception occurred:

Traceback (most recent call last):
  File "C:\Users\lpy\.virtualenvs\bilibili-api--AVx_MxI\lib\site-packages\requests\adapters.py", line 489, in send
    resp = conn.urlopen(
  File "C:\Users\lpy\.virtualenvs\bilibili-api--AVx_MxI\lib\site-packages\urllib3\connectionpool.py", line 787, in urlopen
    retries = retries.increment(
  File "C:\Users\lpy\.virtualenvs\bilibili-api--AVx_MxI\lib\site-packages\urllib3\util\retry.py", line 592, in increment
    raise MaxRetryError(_pool, url, error or ResponseError(cause))
urllib3.exceptions.MaxRetryError: HTTPSConnectionPool(host='api.bilibili.com', port=443): Max retries exceeded with url: /x/web-interface/nav (Caused by SSLError(SSLEOFError(8, 'EOF occurred in violation of protocol (_ssl.c:1129)')))

During handling of the above exception, another exception occurred:

Traceback (most recent call last):
  File "C:\Users\lpy\AppData\Local\Programs\Python\Python39\lib\threading.py", line 973, in _bootstrap_inner
    self.run()
  File "C:\Users\lpy\AppData\Local\Programs\Python\Python39\lib\threading.py", line 910, in run
    self._target(*self._args, **self._kwargs)
  File "C:\Users\lpy\Desktop\bilibili-api\general.py", line 528, in a_
    self.usrJsonObj = get_user_info(headers=self.header)
  File "C:\Users\lpy\Desktop\bilibili-api\module\func.py", line 360, in get_user_info
    response = requests.get(url, headers=headers, timeout=10)
  File "C:\Users\lpy\.virtualenvs\bilibili-api--AVx_MxI\lib\site-packages\requests\sessions.py", line 600, in get
    return self.request("GET", url, **kwargs)
  File "C:\Users\lpy\.virtualenvs\bilibili-api--AVx_MxI\lib\site-packages\requests\sessions.py", line 587, in request
    resp = self.send(prep, **send_kwargs)
  File "C:\Users\lpy\.virtualenvs\bilibili-api--AVx_MxI\lib\site-packages\requests\sessions.py", line 701, in send
    r = adapter.send(request, **kwargs)
  File "C:\Users\lpy\.virtualenvs\bilibili-api--AVx_MxI\lib\site-packages\requests\adapters.py", line 563, in send
    raise SSLError(e, request=request)
requests.exceptions.SSLError: HTTPSConnectionPool(host='api.bilibili.com', port=443): Max retries exceeded with url: /x/web-interface/nav (Caused by SSLError(SSLEOFError(8, 'EOF occurred in violation of protocol (_ssl.c:1129)')))
Exception in thread Thread-2:
Traceback (most recent call last):
  File "C:\Users\lpy\.virtualenvs\bilibili-api--AVx_MxI\lib\site-packages\urllib3\connectionpool.py", line 700, in urlopen
    self._prepare_proxy(conn)
  File "C:\Users\lpy\.virtualenvs\bilibili-api--AVx_MxI\lib\site-packages\urllib3\connectionpool.py", line 996, in _prepare_proxy
    conn.connect()
  File "C:\Users\lpy\.virtualenvs\bilibili-api--AVx_MxI\lib\site-packages\urllib3\connection.py", line 364, in connect
    self.sock = conn = self._connect_tls_proxy(hostname, conn)
  File "C:\Users\lpy\.virtualenvs\bilibili-api--AVx_MxI\lib\site-packages\urllib3\connection.py", line 499, in _connect_tls_proxy
    socket = ssl_wrap_socket(
  File "C:\Users\lpy\.virtualenvs\bilibili-api--AVx_MxI\lib\site-packages\urllib3\util\ssl_.py", line 453, in ssl_wrap_socket
    ssl_sock = _ssl_wrap_socket_impl(sock, context, tls_in_tls)
  File "C:\Users\lpy\.virtualenvs\bilibili-api--AVx_MxI\lib\site-packages\urllib3\util\ssl_.py", line 495, in _ssl_wrap_socket_impl
    return ssl_context.wrap_socket(sock)
  File "C:\Users\lpy\AppData\Local\Programs\Python\Python39\lib\ssl.py", line 500, in wrap_socket
    return self.sslsocket_class._create(
  File "C:\Users\lpy\AppData\Local\Programs\Python\Python39\lib\ssl.py", line 1040, in _create
    self.do_handshake()
  File "C:\Users\lpy\AppData\Local\Programs\Python\Python39\lib\ssl.py", line 1309, in do_handshake
    self._sslobj.do_handshake()
ssl.SSLEOFError: EOF occurred in violation of protocol (_ssl.c:1129)

During handling of the above exception, another exception occurred:

Traceback (most recent call last):
  File "C:\Users\lpy\.virtualenvs\bilibili-api--AVx_MxI\lib\site-packages\requests\adapters.py", line 489, in send
    resp = conn.urlopen(
  File "C:\Users\lpy\.virtualenvs\bilibili-api--AVx_MxI\lib\site-packages\urllib3\connectionpool.py", line 787, in urlopen
    retries = retries.increment(
  File "C:\Users\lpy\.virtualenvs\bilibili-api--AVx_MxI\lib\site-packages\urllib3\util\retry.py", line 592, in increment
    raise MaxRetryError(_pool, url, error or ResponseError(cause))
urllib3.exceptions.MaxRetryError: HTTPSConnectionPool(host='api.bilibili.com', port=443): Max retries exceeded with url: /x/web-interface/view?bvid=BV1EL411U7yA (Caused by SSLError(SSLEOFError(8, 'EOF occurred in violation of protocol (_ssl.c:1129)')))

During handling of the above exception, another exception occurred:

Traceback (most recent call last):
  File "C:\Users\lpy\AppData\Local\Programs\Python\Python39\lib\threading.py", line 973, in _bootstrap_inner
    self.run()
  File "C:\Users\lpy\AppData\Local\Programs\Python\Python39\lib\threading.py", line 910, in run
    self._target(*self._args, **self._kwargs)
  File "C:\Users\lpy\Desktop\bilibili-api\general.py", line 618, in _
    cmd = download_1(i)
  File "C:\Users\lpy\Desktop\bilibili-api\general.py", line 604, in download_1
    P = download_video(bv, self.header, path=setting["path"])
  File "C:\Users\lpy\Desktop\bilibili-api\module\func.py", line 512, in download_video
    json1 = get_video_info(bv, headers)
  File "C:\Users\lpy\Desktop\bilibili-api\module\func.py", line 410, in get_video_info
    cidlist = get_cid(bv, headers)
  File "C:\Users\lpy\Desktop\bilibili-api\module\func.py", line 392, in get_cid
    resp = requests.get(__url, headers=headers, params=data, timeout=10)
  File "C:\Users\lpy\.virtualenvs\bilibili-api--AVx_MxI\lib\site-packages\requests\sessions.py", line 600, in get
    return self.request("GET", url, **kwargs)
  File "C:\Users\lpy\.virtualenvs\bilibili-api--AVx_MxI\lib\site-packages\requests\sessions.py", line 587, in request
    resp = self.send(prep, **send_kwargs)
  File "C:\Users\lpy\.virtualenvs\bilibili-api--AVx_MxI\lib\site-packages\requests\sessions.py", line 701, in send
    r = adapter.send(request, **kwargs)
  File "C:\Users\lpy\.virtualenvs\bilibili-api--AVx_MxI\lib\site-packages\requests\adapters.py", line 563, in send
    raise SSLError(e, request=request)
requests.exceptions.SSLError: HTTPSConnectionPool(host='api.bilibili.com', port=443): Max retries exceeded with url: /x/web-interface/view?bvid=BV1EL411U7yA (Caused by SSLError(SSLEOFError(8, 'EOF occurred in violation of protocol (_ssl.c:1129)')))
Exception in thread Thread-3:
Traceback (most recent call last):
  File "C:\Users\lpy\.virtualenvs\bilibili-api--AVx_MxI\lib\site-packages\urllib3\connectionpool.py", line 700, in urlopen
    self._prepare_proxy(conn)
  File "C:\Users\lpy\.virtualenvs\bilibili-api--AVx_MxI\lib\site-packages\urllib3\connectionpool.py", line 996, in _prepare_proxy
    conn.connect()
  File "C:\Users\lpy\.virtualenvs\bilibili-api--AVx_MxI\lib\site-packages\urllib3\connection.py", line 364, in connect
    self.sock = conn = self._connect_tls_proxy(hostname, conn)
  File "C:\Users\lpy\.virtualenvs\bilibili-api--AVx_MxI\lib\site-packages\urllib3\connection.py", line 499, in _connect_tls_proxy
    socket = ssl_wrap_socket(
  File "C:\Users\lpy\.virtualenvs\bilibili-api--AVx_MxI\lib\site-packages\urllib3\util\ssl_.py", line 453, in ssl_wrap_socket
    ssl_sock = _ssl_wrap_socket_impl(sock, context, tls_in_tls)
  File "C:\Users\lpy\.virtualenvs\bilibili-api--AVx_MxI\lib\site-packages\urllib3\util\ssl_.py", line 495, in _ssl_wrap_socket_impl
    return ssl_context.wrap_socket(sock)
  File "C:\Users\lpy\AppData\Local\Programs\Python\Python39\lib\ssl.py", line 500, in wrap_socket
    return self.sslsocket_class._create(
  File "C:\Users\lpy\AppData\Local\Programs\Python\Python39\lib\ssl.py", line 1040, in _create
    self.do_handshake()
  File "C:\Users\lpy\AppData\Local\Programs\Python\Python39\lib\ssl.py", line 1309, in do_handshake
    self._sslobj.do_handshake()
ssl.SSLEOFError: EOF occurred in violation of protocol (_ssl.c:1129)

During handling of the above exception, another exception occurred:

Traceback (most recent call last):
  File "C:\Users\lpy\.virtualenvs\bilibili-api--AVx_MxI\lib\site-packages\requests\adapters.py", line 489, in send
    resp = conn.urlopen(
  File "C:\Users\lpy\.virtualenvs\bilibili-api--AVx_MxI\lib\site-packages\urllib3\connectionpool.py", line 787, in urlopen
    retries = retries.increment(
  File "C:\Users\lpy\.virtualenvs\bilibili-api--AVx_MxI\lib\site-packages\urllib3\util\retry.py", line 592, in increment
    raise MaxRetryError(_pool, url, error or ResponseError(cause))
urllib3.exceptions.MaxRetryError: HTTPSConnectionPool(host='api.bilibili.com', port=443): Max retries exceeded with url: /x/web-interface/view?bvid=BV1EL411U7yA (Caused by SSLError(SSLEOFError(8, 'EOF occurred in violation of protocol (_ssl.c:1129)')))

During handling of the above exception, another exception occurred:

Traceback (most recent call last):
  File "C:\Users\lpy\AppData\Local\Programs\Python\Python39\lib\threading.py", line 973, in _bootstrap_inner
    self.run()
  File "C:\Users\lpy\AppData\Local\Programs\Python\Python39\lib\threading.py", line 910, in run
    self._target(*self._args, **self._kwargs)
  File "C:\Users\lpy\Desktop\bilibili-api\general.py", line 618, in _
    cmd = download_1(i)
  File "C:\Users\lpy\Desktop\bilibili-api\general.py", line 604, in download_1
    P = download_video(bv, self.header, path=setting["path"])
  File "C:\Users\lpy\Desktop\bilibili-api\module\func.py", line 512, in download_video
    json1 = get_video_info(bv, headers)
  File "C:\Users\lpy\Desktop\bilibili-api\module\func.py", line 410, in get_video_info
    cidlist = get_cid(bv, headers)
  File "C:\Users\lpy\Desktop\bilibili-api\module\func.py", line 392, in get_cid
    resp = requests.get(__url, headers=headers, params=data, timeout=10)
  File "C:\Users\lpy\.virtualenvs\bilibili-api--AVx_MxI\lib\site-packages\requests\sessions.py", line 600, in get
    return self.request("GET", url, **kwargs)
  File "C:\Users\lpy\.virtualenvs\bilibili-api--AVx_MxI\lib\site-packages\requests\sessions.py", line 587, in request
    resp = self.send(prep, **send_kwargs)
  File "C:\Users\lpy\.virtualenvs\bilibili-api--AVx_MxI\lib\site-packages\requests\sessions.py", line 701, in send
    r = adapter.send(request, **kwargs)
  File "C:\Users\lpy\.virtualenvs\bilibili-api--AVx_MxI\lib\site-packages\requests\adapters.py", line 563, in send
    raise SSLError(e, request=request)
requests.exceptions.SSLError: HTTPSConnectionPool(host='api.bilibili.com', port=443): Max retries exceeded with url: /x/web-interface/view?bvid=BV1EL411U7yA (Caused by SSLError(SSLEOFError(8, 'EOF occurred in violation of protocol (_ssl.c:1129)')))
Traceback (most recent call last):
  File "C:\Users\lpy\Desktop\bilibili-api\general.py", line 911, in <module>
    main()
  File "C:\Users\lpy\Desktop\bilibili-api\general.py", line 906, in main
    main1()
  File "C:\Users\lpy\Desktop\bilibili-api\general.py", line 832, in main1
    a = app.exec_()
KeyboardInterrupt
Exception in thread Thread-2:
Traceback (most recent call last):
  File "C:\Users\lpy\AppData\Local\Programs\Python\Python39\lib\site-packages\urllib3\connectionpool.py", line 700, in urlopen
    self._prepare_proxy(conn)
  File "C:\Users\lpy\AppData\Local\Programs\Python\Python39\lib\site-packages\urllib3\connectionpool.py", line 996, in _prepare_proxy
    conn.connect()
  File "C:\Users\lpy\AppData\Local\Programs\Python\Python39\lib\site-packages\urllib3\connection.py", line 364, in connect
    self.sock = conn = self._connect_tls_proxy(hostname, conn)
  File "C:\Users\lpy\AppData\Local\Programs\Python\Python39\lib\site-packages\urllib3\connection.py", line 499, in _connect_tls_proxy
    socket = ssl_wrap_socket(
  File "C:\Users\lpy\AppData\Local\Programs\Python\Python39\lib\site-packages\urllib3\util\ssl_.py", line 453, in ssl_wrap_socket
    ssl_sock = _ssl_wrap_socket_impl(sock, context, tls_in_tls)
  File "C:\Users\lpy\AppData\Local\Programs\Python\Python39\lib\site-packages\urllib3\util\ssl_.py", line 495, in _ssl_wrap_socket_impl
    return ssl_context.wrap_socket(sock)
  File "C:\Users\lpy\AppData\Local\Programs\Python\Python39\lib\ssl.py", line 500, in wrap_socket
    return self.sslsocket_class._create(
  File "C:\Users\lpy\AppData\Local\Programs\Python\Python39\lib\ssl.py", line 1040, in _create
    self.do_handshake()
  File "C:\Users\lpy\AppData\Local\Programs\Python\Python39\lib\ssl.py", line 1309, in do_handshake
    self._sslobj.do_handshake()
ssl.SSLEOFError: EOF occurred in violation of protocol (_ssl.c:1129)

During handling of the above exception, another exception occurred:

Traceback (most recent call last):
  File "C:\Users\lpy\AppData\Local\Programs\Python\Python39\lib\site-packages\requests\adapters.py", line 489, in send
    resp = conn.urlopen(
  File "C:\Users\lpy\AppData\Local\Programs\Python\Python39\lib\site-packages\urllib3\connectionpool.py", line 787, in urlopen
    retries = retries.increment(
  File "C:\Users\lpy\AppData\Local\Programs\Python\Python39\lib\site-packages\urllib3\util\retry.py", line 592, in increment
    raise MaxRetryError(_pool, url, error or ResponseError(cause))
urllib3.exceptions.MaxRetryError: HTTPSConnectionPool(host='api.bilibili.com', port=443): Max retries exceeded with url: /x/web-interface/nav (Caused by SSLError(SSLEOFError(8, 'EOF occurred in violation of protocol (_ssl.c:1129)')))

During handling of the above exception, another exception occurred:

Traceback (most recent call last):
  File "C:\Users\lpy\AppData\Local\Programs\Python\Python39\lib\threading.py", line 973, in _bootstrap_inner
    self.run()
  File "C:\Users\lpy\AppData\Local\Programs\Python\Python39\lib\threading.py", line 910, in run
    self._target(*self._args, **self._kwargs)
  File "C:\Users\lpy\Desktop\bilibili-api\general.py", line 528, in a_
    self.usrJsonObj = get_user_info(headers=self.header)
  File "C:\Users\lpy\Desktop\bilibili-api\module\func.py", line 360, in get_user_info
    response = requests.get(url, headers=headers, timeout=10)
  File "C:\Users\lpy\AppData\Local\Programs\Python\Python39\lib\site-packages\requests\sessions.py", line 600, in get
    return self.request("GET", url, **kwargs)
  File "C:\Users\lpy\AppData\Local\Programs\Python\Python39\lib\site-packages\requests\sessions.py", line 587, in request
    resp = self.send(prep, **send_kwargs)
  File "C:\Users\lpy\AppData\Local\Programs\Python\Python39\lib\site-packages\requests\sessions.py", line 701, in send
    r = adapter.send(request, **kwargs)
  File "C:\Users\lpy\AppData\Local\Programs\Python\Python39\lib\site-packages\requests\adapters.py", line 563, in send
    raise SSLError(e, request=request)
requests.exceptions.SSLError: HTTPSConnectionPool(host='api.bilibili.com', port=443): Max retries exceeded with url: /x/web-interface/nav (Caused by SSLError(SSLEOFError(8, 'EOF occurred in violation of protocol (_ssl.c:1129)')))
Traceback (most recent call last):
  File "C:\Users\lpy\Desktop\bilibili-api\common.py", line 905, in <module>
    main()
  File "C:\Users\lpy\Desktop\bilibili-api\common.py", line 900, in main
    main1()
  File "C:\Users\lpy\Desktop\bilibili-api\common.py", line 827, in main1
    a = app.exec_()
KeyboardInterrupt
Exception in thread Thread-2:
Traceback (most recent call last):
  File "C:\Users\lpy\.virtualenvs\bilibili-api--AVx_MxI\lib\site-packages\urllib3\connectionpool.py", line 700, in urlopen
    self._prepare_proxy(conn)
  File "C:\Users\lpy\.virtualenvs\bilibili-api--AVx_MxI\lib\site-packages\urllib3\connectionpool.py", line 996, in _prepare_proxy
    conn.connect()
  File "C:\Users\lpy\.virtualenvs\bilibili-api--AVx_MxI\lib\site-packages\urllib3\connection.py", line 364, in connect
    self.sock = conn = self._connect_tls_proxy(hostname, conn)
  File "C:\Users\lpy\.virtualenvs\bilibili-api--AVx_MxI\lib\site-packages\urllib3\connection.py", line 499, in _connect_tls_proxy
    socket = ssl_wrap_socket(
  File "C:\Users\lpy\.virtualenvs\bilibili-api--AVx_MxI\lib\site-packages\urllib3\util\ssl_.py", line 453, in ssl_wrap_socket
    ssl_sock = _ssl_wrap_socket_impl(sock, context, tls_in_tls)
  File "C:\Users\lpy\.virtualenvs\bilibili-api--AVx_MxI\lib\site-packages\urllib3\util\ssl_.py", line 495, in _ssl_wrap_socket_impl
    return ssl_context.wrap_socket(sock)
  File "C:\Users\lpy\AppData\Local\Programs\Python\Python39\lib\ssl.py", line 500, in wrap_socket
    return self.sslsocket_class._create(
  File "C:\Users\lpy\AppData\Local\Programs\Python\Python39\lib\ssl.py", line 1040, in _create
    self.do_handshake()
  File "C:\Users\lpy\AppData\Local\Programs\Python\Python39\lib\ssl.py", line 1309, in do_handshake
    self._sslobj.do_handshake()
ssl.SSLEOFError: EOF occurred in violation of protocol (_ssl.c:1129)

During handling of the above exception, another exception occurred:

Traceback (most recent call last):
  File "C:\Users\lpy\.virtualenvs\bilibili-api--AVx_MxI\lib\site-packages\requests\adapters.py", line 489, in send
    resp = conn.urlopen(
  File "C:\Users\lpy\.virtualenvs\bilibili-api--AVx_MxI\lib\site-packages\urllib3\connectionpool.py", line 787, in urlopen
    retries = retries.increment(
  File "C:\Users\lpy\.virtualenvs\bilibili-api--AVx_MxI\lib\site-packages\urllib3\util\retry.py", line 592, in increment
    raise MaxRetryError(_pool, url, error or ResponseError(cause))
urllib3.exceptions.MaxRetryError: HTTPSConnectionPool(host='api.bilibili.com', port=443): Max retries exceeded with url: /x/web-interface/nav (Caused by SSLError(SSLEOFError(8, 'EOF occurred in violation of protocol (_ssl.c:1129)')))

During handling of the above exception, another exception occurred:

Traceback (most recent call last):
  File "C:\Users\lpy\AppData\Local\Programs\Python\Python39\lib\threading.py", line 973, in _bootstrap_inner
    self.run()
  File "C:\Users\lpy\AppData\Local\Programs\Python\Python39\lib\threading.py", line 910, in run
    self._target(*self._args, **self._kwargs)
  File "C:\Users\lpy\Desktop\bilibili-api\general.py", line 528, in a_
    self.usrJsonObj = get_user_info(headers=self.header)
  File "C:\Users\lpy\Desktop\bilibili-api\module\func.py", line 360, in get_user_info
    response = requests.get(url, headers=headers, timeout=10)
  File "C:\Users\lpy\.virtualenvs\bilibili-api--AVx_MxI\lib\site-packages\requests\sessions.py", line 600, in get
    return self.request("GET", url, **kwargs)
  File "C:\Users\lpy\.virtualenvs\bilibili-api--AVx_MxI\lib\site-packages\requests\sessions.py", line 587, in request
    resp = self.send(prep, **send_kwargs)
  File "C:\Users\lpy\.virtualenvs\bilibili-api--AVx_MxI\lib\site-packages\requests\sessions.py", line 701, in send
    r = adapter.send(request, **kwargs)
  File "C:\Users\lpy\.virtualenvs\bilibili-api--AVx_MxI\lib\site-packages\requests\adapters.py", line 563, in send
    raise SSLError(e, request=request)
requests.exceptions.SSLError: HTTPSConnectionPool(host='api.bilibili.com', port=443): Max retries exceeded with url: /x/web-interface/nav (Caused by SSLError(SSLEOFError(8, 'EOF occurred in violation of protocol (_ssl.c:1129)')))
Exception in thread Thread-4:
Traceback (most recent call last):
  File "C:\Users\lpy\AppData\Local\Programs\Python\Python39\lib\threading.py", line 973, in _bootstrap_inner
    self.run()
  File "C:\Users\lpy\AppData\Local\Programs\Python\Python39\lib\threading.py", line 910, in run
    self._target(*self._args, **self._kwargs)
  File "C:\Users\lpy\Desktop\bilibili-api\general.py", line 721, in _
    d(self.result[i - 1]['bvid'])
IndexError: list index out of range
Exception in thread Thread-2:
Traceback (most recent call last):
  File "C:\Users\lpy\AppData\Local\Programs\Python\Python39\lib\site-packages\urllib3\connectionpool.py", line 700, in urlopen
    self._prepare_proxy(conn)
  File "C:\Users\lpy\AppData\Local\Programs\Python\Python39\lib\site-packages\urllib3\connectionpool.py", line 996, in _prepare_proxy
    conn.connect()
  File "C:\Users\lpy\AppData\Local\Programs\Python\Python39\lib\site-packages\urllib3\connection.py", line 364, in connect
    self.sock = conn = self._connect_tls_proxy(hostname, conn)
  File "C:\Users\lpy\AppData\Local\Programs\Python\Python39\lib\site-packages\urllib3\connection.py", line 499, in _connect_tls_proxy
    socket = ssl_wrap_socket(
  File "C:\Users\lpy\AppData\Local\Programs\Python\Python39\lib\site-packages\urllib3\util\ssl_.py", line 453, in ssl_wrap_socket
    ssl_sock = _ssl_wrap_socket_impl(sock, context, tls_in_tls)
  File "C:\Users\lpy\AppData\Local\Programs\Python\Python39\lib\site-packages\urllib3\util\ssl_.py", line 495, in _ssl_wrap_socket_impl
    return ssl_context.wrap_socket(sock)
  File "C:\Users\lpy\AppData\Local\Programs\Python\Python39\lib\ssl.py", line 500, in wrap_socket
    return self.sslsocket_class._create(
  File "C:\Users\lpy\AppData\Local\Programs\Python\Python39\lib\ssl.py", line 1040, in _create
    self.do_handshake()
  File "C:\Users\lpy\AppData\Local\Programs\Python\Python39\lib\ssl.py", line 1309, in do_handshake
    self._sslobj.do_handshake()
socket.timeout: _ssl.c:1112: The handshake operation timed out

During handling of the above exception, another exception occurred:

Traceback (most recent call last):
  File "C:\Users\lpy\AppData\Local\Programs\Python\Python39\lib\site-packages\requests\adapters.py", line 489, in send
    resp = conn.urlopen(
  File "C:\Users\lpy\AppData\Local\Programs\Python\Python39\lib\site-packages\urllib3\connectionpool.py", line 787, in urlopen
    retries = retries.increment(
  File "C:\Users\lpy\AppData\Local\Programs\Python\Python39\lib\site-packages\urllib3\util\retry.py", line 592, in increment
    raise MaxRetryError(_pool, url, error or ResponseError(cause))
urllib3.exceptions.MaxRetryError: HTTPSConnectionPool(host='api.bilibili.com', port=443): Max retries exceeded with url: /x/web-interface/nav (Caused by ProxyError('Cannot connect to proxy.', timeout('_ssl.c:1112: The handshake operation timed out')))

During handling of the above exception, another exception occurred:

Traceback (most recent call last):
  File "C:\Users\lpy\AppData\Local\Programs\Python\Python39\lib\threading.py", line 973, in _bootstrap_inner
    self.run()
  File "C:\Users\lpy\AppData\Local\Programs\Python\Python39\lib\threading.py", line 910, in run
    self._target(*self._args, **self._kwargs)
  File "C:\Users\lpy\Desktop\bilibili-api\general.py", line 527, in a_
    self.usrJsonObj = get_user_info(headers=self.header)
  File "C:\Users\lpy\Desktop\bilibili-api\module\func.py", line 361, in get_user_info
    response = requests.get(url, headers=headers, timeout=10)
  File "C:\Users\lpy\AppData\Local\Programs\Python\Python39\lib\site-packages\requests\sessions.py", line 600, in get
    return self.request("GET", url, **kwargs)
  File "C:\Users\lpy\AppData\Local\Programs\Python\Python39\lib\site-packages\requests\sessions.py", line 587, in request
    resp = self.send(prep, **send_kwargs)
  File "C:\Users\lpy\AppData\Local\Programs\Python\Python39\lib\site-packages\requests\sessions.py", line 701, in send
    r = adapter.send(request, **kwargs)
  File "C:\Users\lpy\AppData\Local\Programs\Python\Python39\lib\site-packages\requests\adapters.py", line 559, in send
    raise ProxyError(e, request=request)
requests.exceptions.ProxyError: HTTPSConnectionPool(host='api.bilibili.com', port=443): Max retries exceeded with url: /x/web-interface/nav (Caused by ProxyError('Cannot connect to proxy.', timeout('_ssl.c:1112: The handshake operation timed out')))
Exception in thread Thread-3:
Traceback (most recent call last):
  File "C:\Users\lpy\AppData\Local\Programs\Python\Python39\lib\site-packages\urllib3\connectionpool.py", line 700, in urlopen
    self._prepare_proxy(conn)
  File "C:\Users\lpy\AppData\Local\Programs\Python\Python39\lib\site-packages\urllib3\connectionpool.py", line 996, in _prepare_proxy
    conn.connect()
  File "C:\Users\lpy\AppData\Local\Programs\Python\Python39\lib\site-packages\urllib3\connection.py", line 364, in connect
    self.sock = conn = self._connect_tls_proxy(hostname, conn)
  File "C:\Users\lpy\AppData\Local\Programs\Python\Python39\lib\site-packages\urllib3\connection.py", line 499, in _connect_tls_proxy
    socket = ssl_wrap_socket(
  File "C:\Users\lpy\AppData\Local\Programs\Python\Python39\lib\site-packages\urllib3\util\ssl_.py", line 453, in ssl_wrap_socket
    ssl_sock = _ssl_wrap_socket_impl(sock, context, tls_in_tls)
  File "C:\Users\lpy\AppData\Local\Programs\Python\Python39\lib\site-packages\urllib3\util\ssl_.py", line 495, in _ssl_wrap_socket_impl
    return ssl_context.wrap_socket(sock)
  File "C:\Users\lpy\AppData\Local\Programs\Python\Python39\lib\ssl.py", line 500, in wrap_socket
    return self.sslsocket_class._create(
  File "C:\Users\lpy\AppData\Local\Programs\Python\Python39\lib\ssl.py", line 1040, in _create
    self.do_handshake()
  File "C:\Users\lpy\AppData\Local\Programs\Python\Python39\lib\ssl.py", line 1309, in do_handshake
    self._sslobj.do_handshake()
socket.timeout: _ssl.c:1112: The handshake operation timed out

During handling of the above exception, another exception occurred:

Traceback (most recent call last):
  File "C:\Users\lpy\AppData\Local\Programs\Python\Python39\lib\site-packages\requests\adapters.py", line 489, in send
    resp = conn.urlopen(
  File "C:\Users\lpy\AppData\Local\Programs\Python\Python39\lib\site-packages\urllib3\connectionpool.py", line 787, in urlopen
    retries = retries.increment(
  File "C:\Users\lpy\AppData\Local\Programs\Python\Python39\lib\site-packages\urllib3\util\retry.py", line 592, in increment
    raise MaxRetryError(_pool, url, error or ResponseError(cause))
urllib3.exceptions.MaxRetryError: HTTPSConnectionPool(host='api.bilibili.com', port=443): Max retries exceeded with url: /x/web-interface/nav (Caused by ProxyError('Cannot connect to proxy.', timeout('_ssl.c:1112: The handshake operation timed out')))

During handling of the above exception, another exception occurred:

Traceback (most recent call last):
  File "C:\Users\lpy\AppData\Local\Programs\Python\Python39\lib\threading.py", line 973, in _bootstrap_inner
    self.run()
  File "C:\Users\lpy\AppData\Local\Programs\Python\Python39\lib\threading.py", line 910, in run
    self._target(*self._args, **self._kwargs)
  File "C:\Users\lpy\Desktop\bilibili-api\general.py", line 527, in a_
    self.usrJsonObj = get_user_info(headers=self.header)
  File "C:\Users\lpy\Desktop\bilibili-api\module\func.py", line 361, in get_user_info
    response = requests.get(url, headers=headers, timeout=10)
  File "C:\Users\lpy\AppData\Local\Programs\Python\Python39\lib\site-packages\requests\sessions.py", line 600, in get
    return self.request("GET", url, **kwargs)
  File "C:\Users\lpy\AppData\Local\Programs\Python\Python39\lib\site-packages\requests\sessions.py", line 587, in request
    resp = self.send(prep, **send_kwargs)
  File "C:\Users\lpy\AppData\Local\Programs\Python\Python39\lib\site-packages\requests\sessions.py", line 701, in send
    r = adapter.send(request, **kwargs)
  File "C:\Users\lpy\AppData\Local\Programs\Python\Python39\lib\site-packages\requests\adapters.py", line 559, in send
    raise ProxyError(e, request=request)
requests.exceptions.ProxyError: HTTPSConnectionPool(host='api.bilibili.com', port=443): Max retries exceeded with url: /x/web-interface/nav (Caused by ProxyError('Cannot connect to proxy.', timeout('_ssl.c:1112: The handshake operation timed out')))
Exception in thread Thread-4:
Traceback (most recent call last):
  File "C:\Users\lpy\Desktop\bilibili-api\general.py", line 512, in a_
    raise ValueError(
ValueError: Cookie must be a string, not a <class 'dict'>

During handling of the above exception, another exception occurred:

Traceback (most recent call last):
  File "C:\Users\lpy\AppData\Local\Programs\Python\Python39\lib\site-packages\urllib3\connectionpool.py", line 700, in urlopen
    self._prepare_proxy(conn)
  File "C:\Users\lpy\AppData\Local\Programs\Python\Python39\lib\site-packages\urllib3\connectionpool.py", line 996, in _prepare_proxy
    conn.connect()
  File "C:\Users\lpy\AppData\Local\Programs\Python\Python39\lib\site-packages\urllib3\connection.py", line 364, in connect
    self.sock = conn = self._connect_tls_proxy(hostname, conn)
  File "C:\Users\lpy\AppData\Local\Programs\Python\Python39\lib\site-packages\urllib3\connection.py", line 499, in _connect_tls_proxy
    socket = ssl_wrap_socket(
  File "C:\Users\lpy\AppData\Local\Programs\Python\Python39\lib\site-packages\urllib3\util\ssl_.py", line 453, in ssl_wrap_socket
    ssl_sock = _ssl_wrap_socket_impl(sock, context, tls_in_tls)
  File "C:\Users\lpy\AppData\Local\Programs\Python\Python39\lib\site-packages\urllib3\util\ssl_.py", line 495, in _ssl_wrap_socket_impl
    return ssl_context.wrap_socket(sock)
  File "C:\Users\lpy\AppData\Local\Programs\Python\Python39\lib\ssl.py", line 500, in wrap_socket
    return self.sslsocket_class._create(
  File "C:\Users\lpy\AppData\Local\Programs\Python\Python39\lib\ssl.py", line 1040, in _create
    self.do_handshake()
  File "C:\Users\lpy\AppData\Local\Programs\Python\Python39\lib\ssl.py", line 1309, in do_handshake
    self._sslobj.do_handshake()
socket.timeout: _ssl.c:1112: The handshake operation timed out

During handling of the above exception, another exception occurred:

Traceback (most recent call last):
  File "C:\Users\lpy\AppData\Local\Programs\Python\Python39\lib\site-packages\requests\adapters.py", line 489, in send
    resp = conn.urlopen(
  File "C:\Users\lpy\AppData\Local\Programs\Python\Python39\lib\site-packages\urllib3\connectionpool.py", line 787, in urlopen
    retries = retries.increment(
  File "C:\Users\lpy\AppData\Local\Programs\Python\Python39\lib\site-packages\urllib3\util\retry.py", line 592, in increment
    raise MaxRetryError(_pool, url, error or ResponseError(cause))
urllib3.exceptions.MaxRetryError: HTTPSConnectionPool(host='api.bilibili.com', port=443): Max retries exceeded with url: /x/web-interface/nav (Caused by ProxyError('Cannot connect to proxy.', timeout('_ssl.c:1112: The handshake operation timed out')))

During handling of the above exception, another exception occurred:

Traceback (most recent call last):
  File "C:\Users\lpy\AppData\Local\Programs\Python\Python39\lib\threading.py", line 973, in _bootstrap_inner
    self.run()
  File "C:\Users\lpy\AppData\Local\Programs\Python\Python39\lib\threading.py", line 910, in run
    self._target(*self._args, **self._kwargs)
  File "C:\Users\lpy\Desktop\bilibili-api\general.py", line 520, in a_
    a_()
  File "C:\Users\lpy\Desktop\bilibili-api\general.py", line 527, in a_
    self.usrJsonObj = get_user_info(headers=self.header)
  File "C:\Users\lpy\Desktop\bilibili-api\module\func.py", line 361, in get_user_info
    response = requests.get(url, headers=headers, timeout=10)
  File "C:\Users\lpy\AppData\Local\Programs\Python\Python39\lib\site-packages\requests\sessions.py", line 600, in get
    return self.request("GET", url, **kwargs)
  File "C:\Users\lpy\AppData\Local\Programs\Python\Python39\lib\site-packages\requests\sessions.py", line 587, in request
    resp = self.send(prep, **send_kwargs)
  File "C:\Users\lpy\AppData\Local\Programs\Python\Python39\lib\site-packages\requests\sessions.py", line 701, in send
    r = adapter.send(request, **kwargs)
  File "C:\Users\lpy\AppData\Local\Programs\Python\Python39\lib\site-packages\requests\adapters.py", line 559, in send
    raise ProxyError(e, request=request)
requests.exceptions.ProxyError: HTTPSConnectionPool(host='api.bilibili.com', port=443): Max retries exceeded with url: /x/web-interface/nav (Caused by ProxyError('Cannot connect to proxy.', timeout('_ssl.c:1112: The handshake operation timed out')))
Exception in thread Thread-6:
Traceback (most recent call last):
  File "C:\Users\lpy\AppData\Local\Programs\Python\Python39\lib\site-packages\urllib3\connectionpool.py", line 700, in urlopen
    self._prepare_proxy(conn)
  File "C:\Users\lpy\AppData\Local\Programs\Python\Python39\lib\site-packages\urllib3\connectionpool.py", line 996, in _prepare_proxy
    conn.connect()
  File "C:\Users\lpy\AppData\Local\Programs\Python\Python39\lib\site-packages\urllib3\connection.py", line 364, in connect
    self.sock = conn = self._connect_tls_proxy(hostname, conn)
  File "C:\Users\lpy\AppData\Local\Programs\Python\Python39\lib\site-packages\urllib3\connection.py", line 499, in _connect_tls_proxy
    socket = ssl_wrap_socket(
  File "C:\Users\lpy\AppData\Local\Programs\Python\Python39\lib\site-packages\urllib3\util\ssl_.py", line 453, in ssl_wrap_socket
    ssl_sock = _ssl_wrap_socket_impl(sock, context, tls_in_tls)
  File "C:\Users\lpy\AppData\Local\Programs\Python\Python39\lib\site-packages\urllib3\util\ssl_.py", line 495, in _ssl_wrap_socket_impl
    return ssl_context.wrap_socket(sock)
  File "C:\Users\lpy\AppData\Local\Programs\Python\Python39\lib\ssl.py", line 500, in wrap_socket
    return self.sslsocket_class._create(
  File "C:\Users\lpy\AppData\Local\Programs\Python\Python39\lib\ssl.py", line 1040, in _create
    self.do_handshake()
  File "C:\Users\lpy\AppData\Local\Programs\Python\Python39\lib\ssl.py", line 1309, in do_handshake
    self._sslobj.do_handshake()
socket.timeout: _ssl.c:1112: The handshake operation timed out

During handling of the above exception, another exception occurred:

Traceback (most recent call last):
  File "C:\Users\lpy\AppData\Local\Programs\Python\Python39\lib\site-packages\requests\adapters.py", line 489, in send
    resp = conn.urlopen(
  File "C:\Users\lpy\AppData\Local\Programs\Python\Python39\lib\site-packages\urllib3\connectionpool.py", line 787, in urlopen
    retries = retries.increment(
  File "C:\Users\lpy\AppData\Local\Programs\Python\Python39\lib\site-packages\urllib3\util\retry.py", line 592, in increment
    raise MaxRetryError(_pool, url, error or ResponseError(cause))
urllib3.exceptions.MaxRetryError: HTTPSConnectionPool(host='api.bilibili.com', port=443): Max retries exceeded with url: /x/web-interface/nav (Caused by ProxyError('Cannot connect to proxy.', timeout('_ssl.c:1112: The handshake operation timed out')))

During handling of the above exception, another exception occurred:

Traceback (most recent call last):
  File "C:\Users\lpy\AppData\Local\Programs\Python\Python39\lib\threading.py", line 973, in _bootstrap_inner
    self.run()
  File "C:\Users\lpy\AppData\Local\Programs\Python\Python39\lib\threading.py", line 910, in run
    self._target(*self._args, **self._kwargs)
  File "C:\Users\lpy\Desktop\bilibili-api\general.py", line 527, in a_
    self.usrJsonObj = get_user_info(headers=self.header)
  File "C:\Users\lpy\Desktop\bilibili-api\module\func.py", line 361, in get_user_info
    response = requests.get(url, headers=headers, timeout=10)
  File "C:\Users\lpy\AppData\Local\Programs\Python\Python39\lib\site-packages\requests\sessions.py", line 600, in get
    return self.request("GET", url, **kwargs)
  File "C:\Users\lpy\AppData\Local\Programs\Python\Python39\lib\site-packages\requests\sessions.py", line 587, in request
    resp = self.send(prep, **send_kwargs)
  File "C:\Users\lpy\AppData\Local\Programs\Python\Python39\lib\site-packages\requests\sessions.py", line 701, in send
    r = adapter.send(request, **kwargs)
  File "C:\Users\lpy\AppData\Local\Programs\Python\Python39\lib\site-packages\requests\adapters.py", line 559, in send
    raise ProxyError(e, request=request)
requests.exceptions.ProxyError: HTTPSConnectionPool(host='api.bilibili.com', port=443): Max retries exceeded with url: /x/web-interface/nav (Caused by ProxyError('Cannot connect to proxy.', timeout('_ssl.c:1112: The handshake operation timed out')))
Traceback (most recent call last):
  File "C:\Users\lpy\Desktop\bilibili-api\general.py", line 911, in <module>
    main()
  File "C:\Users\lpy\Desktop\bilibili-api\general.py", line 906, in main
    main1()
  File "C:\Users\lpy\Desktop\bilibili-api\general.py", line 832, in main1
    a = app.exec_()
KeyboardInterrupt
